Workbook

Sheet READ ME FIRST
A1: Cornerstone III Practice — Your Miami Month
A3: The setup | B3: You have graduated and taken a job in Miami. The randomiser deals you a role, a salary, a neighborhood, and a student-loan balance. Everybody's hand is different, so there is nothing to copy.
A4: Roll once, then lock it | B4: RANDBETWEEN re-rolls every time the sheet recalculates. Roll your hand, then select those cells, copy, and Paste Special > Values to freeze them. That is your life for this cornerstone.
A5: Florida has no state income tax | B5: That is a real advantage and drill 3 makes you put a number on it. Federal income tax and FICA still apply — take-home is not salary divided by twelve.
A6: Rents are approximate | B6: The neighborhood table holds modelling values, not quotes. Drill 2 asks you to check one against a real listing and report the gap. Models built on unchecked numbers are how people get hurt.
A7: The point | B7: A budget that only works in the expected month is not a budget. You will break yours on purpose.

Sheet Reference Tables
A1: Reference Tables
A2: Look values up from here. Never type them into your model.
A4: NEIGHBORHOODS
A5: Neighborhood | B5: Median 1BR rent | C5: Commute (min) | D5: Notes
A6: Brickell | B6: 3000 | C6: 10 | D6: High-rise downtown core; walkable, priciest
A7: Downtown | B7: 2700 | C7: 10 | D7: Metromover access; busy, mixed
A8: Edgewater | B8: 2900 | C8: 15 | D8: Bayfront, newer towers
A9: Wynwood | B9: 2800 | C9: 15 | D9: Arts district; converted warehouses
A10: Design District | B10: 3200 | C10: 15 | D10: Luxury retail; small rental stock
A11: Midtown | B11: 2850 | C11: 15 | D11: Between Wynwood and Design District
A12: Coral Gables | B12: 2900 | C12: 25 | D12: Tree-lined, quiet, good commute south
A13: Coconut Grove | B13: 3100 | C13: 25 | D13: Waterfront, village feel
A14: South Miami | B14: 2400 | C14: 30 | D14: Suburban, near the Metrorail
A15: Little Havana | B15: 1900 | C15: 15 | D15: Historic Cuban core; older stock
A16: Allapattah | B16: 1800 | C16: 15 | D16: Rapidly changing; near the hospital district
A17: Little Haiti | B17: 1750 | C17: 20 | D17: Historic; rising quickly
... A22: Miami Beach | B22: 2600 | C22: 35 | D22: Across the causeway; parking is a cost
A24: ROLES
A25: Job title | B25: Gross salary
A26: Junior software developer | B26: 72000
A27: Marketing coordinator | B27: 48000
A28: Registered nurse | B28: 75000
A29: Civil engineer (EIT) | B29: 68000
A30: Paralegal | B30: 52000
A31: Financial analyst | B31: 70000
A32: Teacher, first year | B32: 47500
A33: Graphic designer | B33: 50000
A34: Mechanical engineer | B34: 71000
A35: Sales representative | B35: 55000
A36: Lab technician | B36: 46000
A37: Architectural designer | B37: 58000
A39: CURVEBALLS
A40: Event | B40: Amount | C40: How it hits
A41: Hurricane deductible after a named storm | B41: 2500 | C41: one-time
A42: Car repair — pothole on the 826 | B42: 900 | C42: one-time
A43: Rent hike at renewal (+8%) | B43: 0 | C43: recurring: rent x 1.08
A44: Hours cut 15% for two months | B44: 0 | C44: recurring: income x 0.85
A45: AC compressor dies in August | B45: 1200 | C45: one-time
A46: Health premium increase | B46: 85 | C46: recurring: monthly
A47: Towed and impounded during King Tide flooding | B47: 600 | C47: one-time
...

Sheet 1 Roll Your Life
A1: Drill 1 — Roll your life
A2: Press F9 to re-roll. When you like your hand — or accept the one you got — copy these cells and Paste Special > Values to lock them.
A4: Neighborhood roll | B4: =RANDBETWEEN(1,17) | D4: INDEX pulls the row the roll landed on. Read the formula — this is the same lookup move from Cornerstone I, doing real work.
A5: Role roll | B5: =RANDBETWEEN(1,12)
A6: Student loan balance | B6: =RANDBETWEEN(0,45)*1000
A8: YOUR HAND
A9: Neighborhood | B9: =INDEX('Reference Tables'!$A$6:$A$22,$B$4)
A10: Median 1BR rent | B10: =INDEX('Reference Tables'!$B$6:$B$22,$B$4)
A11: Commute (min each way) | B11: =INDEX('Reference Tables'!$C$6:$C$22,$B$4)
A12: Job title | B12: =INDEX('Reference Tables'!$A$26:$A$37,$B$5)
A13: Gross salary | B13: =INDEX('Reference Tables'!$B$26:$B$37,$B$5)
A14: Student loan balance | B14: =$B$6

Sheet 2 Verify The Rent
A1: Drill 2 — Check the number against reality
A2: The reference table holds approximate medians. Find one real listing in your neighborhood.
A4: Your neighborhood
A5: Table value (median 1BR)
A6: Real listing you found (URL)
A7: Real listing rent
A8: Difference | B8: =B7-B5
A9: Percent difference | B9: =IF(B5=0,"",(B7-B5)/B5)
A11: Which number will you build your budget on, and why? (Two sentences.)

Sheet 3 Take-Home Pay
A1: Drill 3 — Salary is not take-home
A2: Build gross to net. Florida has no state income tax; put a dollar value on that.
A4: Gross annual salary | B4: ='1 Roll Your Life'!B13
A5: Standard deduction (single, approx.) | B5: =15000
A6: Taxable income | B6: =MAX(0,B4-B5)
A7: Federal income tax (approx. effective) | B7: =B6*0.12
A8: FICA (7.65%) | B8: =B4*0.0765
A9: Florida state income tax | B9: =0 | D9: Zero — and that is the point. Drill: what would this cell say if you took the same job in New York (about 6%) or California (about 8%)? Compute both and write the monthly difference below.
A10: Net annual | B10: =B4-B7-B8-B9
A11: Take-home per month | B11: =B10/12
A13: Monthly value of living in Florida vs New York | B13: =B6*0.06/12
A14: Monthly value vs California | B14: =B6*0.08/12

Sheet 4-5 Baseline vs Curveball
A1: Drills 4 & 5 — The month, twice
A2: Classify every line as fixed or variable, then run it again with a curveball.
A4: Category | B4: Fixed or variable? | C4: Baseline | D4: With curveball
A5: Rent | B5: Fixed | C5: ='1 Roll Your Life'!B10 | D5: =C5
A6: Renter's insurance | B6: Fixed | C6: 25 | D6: =C6
A7: Electricity (FPL) | B7: Variable | C7: 140 | D7: =C7
A8: Internet | B8: Fixed | C8: 70 | D8: =C8
A9: Phone | B9: Fixed | C9: 55 | D9: =C9
A10: Groceries | B10: Variable | C10: 400 | D10: =C10
A11: Eating out | B11: Variable | C11: 220 | D11: =C11
A12: Car payment | B12: Fixed | C12: 380 | D12: =C12
A13: Car insurance (Miami rates) | B13: Fixed | C13: 245 | D13: =C13
A14: Gas / tolls (SunPass) | B14: Variable | C14: 160 | D14: =C14
A15: Parking | B15: Fixed | C15: 90 | D15: =C15
A16: Student loan payment | B16: Fixed | C16: 250 | D16: =C16
A17: Health insurance | B17: Fixed | C17: 210 | D17: =C17
... A19: Going out | B19: Variable | C19: 180 | D19: =C19
A20: TOTAL SPENDING | C20: =SUM(C5:C19) | D20: =SUM(D5:D19)
A21: Take-home | C21: ='3 Take-Home Pay'!B11 | D21: =C21
A22: LEFT OVER | C22: =C21-C20 | D22: =D21-D20
A23: SAVINGS RATE | C23: =IF(C21=0,"",C22/C21) | D23: =IF(D21=0,"",D22/D21)
A25: Months until savings hit zero (curveball month repeating) | C25: =IF(D22>=0,"never — it holds",ROUND(1000/-D22,1)) | E25: Drill 5: pick a curveball from the Reference Tables and apply it in column D only. Assume $1,000 in savings. Does your month hold?
